2017-04-27 14:50:47,445 [django.request] ERROR: Internal Server Error: /
Traceback (most recent call last):
  File "/usr/local/lib/python3.4/site-packages/django/db/backends/utils.py", line 64, in execute
    return self.cursor.execute(sql, params)
psycopg2.ProgrammingError: relation "blog_blog" does not exist
LINE 1: SELECT COUNT(*) AS "__count" FROM "blog_blog"
                                          ^


The above exception was the direct cause of the following exception:

Traceback (most recent call last):
  File "/usr/local/lib/python3.4/site-packages/django/core/handlers/exception.py", line 42, in inner
    response = get_response(request)
  File "/usr/local/lib/python3.4/site-packages/django/core/handlers/base.py", line 187, in _get_response
    response = self.process_exception_by_middleware(e, request)
  File "/usr/local/lib/python3.4/site-packages/django/core/handlers/base.py", line 185, in _get_response
    response = wrapped_callback(request, *callback_args, **callback_kwargs)
  File "/code/blog/views.py", line 10, in list
    p = Paginator(blogs, 7).page(page)
  File "/usr/local/lib/python3.4/site-packages/django/core/paginator.py", line 50, in page
    number = self.validate_number(number)
  File "/usr/local/lib/python3.4/site-packages/django/core/paginator.py", line 39, in validate_number
    if number > self.num_pages:
  File "/usr/local/lib/python3.4/site-packages/django/utils/functional.py", line 35, in __get__
    res = instance.__dict__[self.name] = self.func(instance)
  File "/usr/local/lib/python3.4/site-packages/django/core/paginator.py", line 84, in num_pages
    if self.count == 0 and not self.allow_empty_first_page:
  File "/usr/local/lib/python3.4/site-packages/django/utils/functional.py", line 35, in __get__
    res = instance.__dict__[self.name] = self.func(instance)
  File "/usr/local/lib/python3.4/site-packages/django/core/paginator.py", line 72, in count
    return self.object_list.count()
  File "/usr/local/lib/python3.4/site-packages/django/db/models/query.py", line 369, in count
    return self.query.get_count(using=self.db)
  File "/usr/local/lib/python3.4/site-packages/django/db/models/sql/query.py", line 476, in get_count
    number = obj.get_aggregation(using, ['__count'])['__count']
  File "/usr/local/lib/python3.4/site-packages/django/db/models/sql/query.py", line 457, in get_aggregation
    result = compiler.execute_sql(SINGLE)
  File "/usr/local/lib/python3.4/site-packages/django/db/models/sql/compiler.py", line 835, in execute_sql
    cursor.execute(sql, params)
  File "/usr/local/lib/python3.4/site-packages/django/db/backends/utils.py", line 64, in execute
    return self.cursor.execute(sql, params)
  File "/usr/local/lib/python3.4/site-packages/django/db/utils.py", line 94, in __exit__
    six.reraise(dj_exc_type, dj_exc_value, traceback)
  File "/usr/local/lib/python3.4/site-packages/django/utils/six.py", line 685, in reraise
    raise value.with_traceback(tb)
  File "/usr/local/lib/python3.4/site-packages/django/db/backends/utils.py", line 64, in execute
    return self.cursor.execute(sql, params)
django.db.utils.ProgrammingError: relation "blog_blog" does not exist
LINE 1: SELECT COUNT(*) AS "__count" FROM "blog_blog"
                                          ^

